Workbook

Sheet Hoja1
H3: 20 DE FEBRERO DEL 2023
B9: PROYECTO: | C9: TORRE PARALLEL | H9: PEDIDO #335
B10: DIRECCIÓN: | C10: VISTA REAL MZ III Lt. 14, COL. GREEN HOUSE
C11: SEGUNDA ETAPA HUIXQUILUCAN, EDO. DE MÉXICO.
B15: ATN: DANIEL RUIZ; HUMBERTO JIMENEZ | H15: GIOVANNI
B17: # | C17: CONCEPTO | F17: UNIDAD | G17: PEDIDO | H17: OBSERVACIONES
B19: 1 | C19: SERVICIO A IMPRESORA EN OBRA | F19: LOTE | G19: 1
B23: FORMULÓ:
B25: ARQ. JONHATAN ALEJANDRO CANO MUNIVE

Sheet RESPALDO
E2: Cd. De México a 06 de Noviembre del 2025
E4: PROVEEDOR: | F4: JUAN ALEJANDRO CHAVEZ
F5: AV. NELLIE CAMPOBELLO No.. 129 EDIF. CORA DEPTO 604
F6: COL. CAROLA
F7: DELG. ALVARO OBREGON
E10: ATENCION: | F10: ALEJANDRO CHAVEZ
B11: HEG DISEÑO E INSTALACION, S.A. DE C.V.
B13: PEDIDO: | C13: 250
B14: FAMILIA: | C14: EM | E14: PROYECTO: | F14: 00443 JAIME NUNO
B15: CONCEPTO: | C15: EMPAQUES | E15: CLAN: | F15: MATERIALES
E16: ENTREGAR EN: | F16: JAIME NUNO
F17: INSURGENTES SUR 1921
F18: Col. GUADALUPE INN
F19: DEL. ALVARO OBREGON
F20: CP 01020
B23: NO. | C23: DESCRIPCION | D23: UNIDAD | E23: MEDIDA | G23: CANTIDAD | H23: P. UNITARIO | I23: IMPORTE | J23: CLAVE | K23: DIBUJO | L23: M.L. | M23: ACABADO | N23: KG | O23: PRECIOxKG
B24: 1 | C24: EMPAQUE DE SANTOPRENO HONGO MEDIANO | D24: ROLLO DE 100 MTS. | G24: 3 | H24: 780 | I24: =H24*G24 -> 2340 | L24: 300 | M24: COLOR NEGRO | N24: 18 | O24: =I24/N24 -> 130
B25: 2 | C25: EMPAQUE DE SANTOPRENO RESPALDO CRISTAL | D25: ROLLO DE 100 MTS. | G25: 1 | H25: 585 | I25: =H25*G25 -> 585 | L25: 100 | M25: COLOR NEGRO | N25: 4.5 | O25: =I25/N25 -> 130
B26: 3 | C26: EMPAQUE DE SANTOPRENO MEDIA LUNA CHICA | D26: ROLLO DE 100 MTS. | G26: 2.5 | H26: 390 | I26: =H26*G26 -> 975 | L26: 250 | M26: COLOR NEGRO | N26: 7.5 | O26: =I26/N26 -> 130
B27: 4 | C27: FELPA DE 7 X 5 CON PELO INTERMEDIO | D27: ROLLO DE 100 MTS. | G27: 1 | H27: 3 | I27: 300 | L27: 100 | M27: COLOR NEGRO | N27: 0 | O27: =I27/N27 -> #DIV/0!
B28: 5 | I28: =H28*G28 -> 0
B29: 6 | I29: =H29*G29 -> 0
B30: 7 | I30: =H30*G30 -> 0
B31: 8 | I31: =H31*G31 -> 0
B32: 9 | I32: =H32*G32 -> 0
B33: 10 | I33: =H33*G33 -> 0
B34: 11 | I34: =H34*G34 -> 0
B35: 12 | I35: =H35*G35 -> 0
B36: 13 | I36: =H36*G36 -> 0
B37: 14 | I37: =H37*G37 -> 0
H39: IMPORTE | I39: =SUM(I24:I37) -> 4200
C40: PAGOS INMEDIATOS | H40: DESCUENTO | L40: -
C41: APROBADO | H41: SUBTOTAL | I41: =+I39-I40 -> 4200 | L41: SITUACIONES ESPECIALES
C42: 06/11/2025 | H42: IVA | I42: =+I41*0.16 -> 672
C43: FECHA DE APROBACION | H43: TOTAL | I43: =+I41+I42 -> 4872
C45: FORMULÓ
C46: D. ERICK RUIZ

Sheet CATALOGO
A1: DESCRIPCION | B1: CLAVE | C1: P. UNITARIO | D1: MONEDA
A2: 94 PRIMER 3M SCOTCH-WELD PROMOTOR DE ADHESIÓN PARA UNA GRAN VARIEDAD DE SUSTRATOS, 0.946 L , CLARO
A3: ABRAZADERA SIN FIN
A4: ABRAZADERA SNAPLOCK
A5: ABRAZADERA SOLERA 48 mm. BROCHE [ACCAS48BRO]
A6: ABRAZADERA SOLERA 60 mm. BROCHE [ACCAS60BRO]
A7: ABRAZADERA TORNILLO DE 48 MM [ACCAT48]
A8: ABRAZADERA TORNILLO DE 60 MM [ACCAT60]
A9: ACEITE PARA CORTE ALUMINIO
A10: ADAPTACION DE RIELES PARA TALADRO MULTIPLE FELDER FD21 CON NIVELADORES RODAJA
A11: ADAPTACION DE RIELES SIERRAS DE DISCO
A12: ADAPTADOR IMPACTO 1/4" A 1/2"
A13: ADHESIVO ESTRUCTURAL SIKASIL SG 18 NEGRO MATE
... A1017: ZOCLO CABEZAL S70
A1018: 30M LD030P MAKITA | B1018: 3909 | C1018: 1838 | D1018: MXP
A1019: ACRILASTIC SELLADOR ACRÍLICO - BEIGE | B1019: ROD-25 | C1019: 46 | D1019: MXP
A1020: ACRILASTIC SELLADOR ACRÍLICO - BLANCO | B1020: ROD-23 | C1020: 46 | D1020: MXP
A1021: ACRILASTIC SELLADOR ACRÍLICO - GRIS | B1021: ROD-26 | C1021: 46 | D1021: MXP
A1022: ACRILASTIC SELLADOR ACRÍLICO - NEGRO | B1022: ROD-24 | C1022: 46 | D1022: MXP
A1023: ACRILICO MEDIA LUNA PARA RETENER AGUA EN PISO, DE 12X6MM L=2.5MTS CON CINTA ADHESIVA | B1023: 01170121 | C1023: =145.6*0.8*0.95 -> 110.656 | D1023: MXP
A1024: ALCOHOL ISOPROPILICO | B1024: ROD-46 | C1024: 60 | D1024: MXP
A1025: ALETA LARGA 135 P/ CRISTAL 10MM L=2.5 METROS | B1025: 01170105 | C1025: =51.45*0.8*0.95 -> 39.102 | D1025: MXP
A1026: ANCLA BASE PARA MARQUESINA ACERO INOX 304 | B1026: 14010101 | C1026: =556.5*0.8*0.95 -> 422.94 | D1026: MXP
A1027: ANCLA DOBLE MURO CRISTAL PARA MARQUESINA ACERO INOX 304 | B1027: 14010501 | C1027: =2369.5*0.8*0.95 -> 1800.82 | D1027: MXP
A1028: ANCLA SIMPLE MURO CRISTAL PARA MARQUESINA ACERO INOX 304 | B1028: 14010401 | C1028: =1256.5*0.8*0.95 -> 954.94 | D1028: MXP
A1029: ANGULO C-C 90° INOVA, NÍQUEL SATINADO | B1029: 01030202 | C1029: =573.99*0.8*0.95 -> 436.2324 | D1029: MXP
A1030: ANGULO C-C 90° INOVA,CROMO BRILLANTE | B1030: 01030201 | C1030: =558.94*0.8*0.95 -> 424.7944 | D1030: MXP
A1031: ANGULO C-C AQUA LIGHT 90°, CROMO BRILLANTE | B1031: 01070201 | C1031: =404.49*0.8*0.95 -> 307.4124 | D1031: MXP
A1032: ANGULO C-C AQUA LIGHT 90°, NÍQUEL SATINADO | B1032: 01070202 | C1032: =416.43*0.8*0.95 -> 316.4868 | D1032: MXP
A1033: ANGULO DE ALUMINIO 1/4" DE 3"X2"X200MM C/2 BARRENOS ANODIZADO NATURAL MATE | B1033: 13110401 | C1033: =220.85*0.8*0.95 -> 167.846 | D1033: MXP
A1034: ANGULO DE ALUMINIO 1/4" DE 3"X2"X250MM C/2 BARRENOS ANODIZADO NATURAL MATE | B1034: 13110402 | C1034: =244.63*0.8*0.95 -> 185.9188 | D1034: MXP
A1035: ANGULO DE ALUMINIO 1/4" DE 3"X2"X300MM C/3 BARRENOS ANODIZADO NATURAL MATE | B1035: 13110403 | C1035: =299.09*0.8*0.95 -> 227.3084 | D1035: MXP
A1036: ANGULO DE ALUMINIO 1/4" DE 3"X2"X350MM C/3 BARRENOS ANODIZADO NATURAL MATE | B1036: 13110404 | C1036: =331.4*0.8*0.95 -> 251.864 | D1036: MXP
A1037: ANGULO DE ALUMINIO 1/4" DE 3"X2"X400MM C/3 BARRENOS ANODIZADO NATURAL MATE | B1037: 13110405 | C1037: =394.86*0.8*0.95 -> 300.0936 | D1037: MXP
A1038: ANGULO INOVA C/C EN T CROMO BRILLANTE | B1038: 01030401 | C1038: =805.8*0.8*0.95 -> 612.408 | D1038: MXP
A1039: ANGULO INOVA C-C EN T NIQ SATINADO | B1039: 01030402 | C1039: =824.25*0.8*0.95 -> 626.43 | D1039: MXP
A1040: ANGULO INOVA M/C EN T CROMO BRILLANTE | B1040: 01030301 | C1040: =475.57*0.8*0.95 -> 361.4332 | D1040: MXP
A1041: ANGULO INOVA M/C EN T NIQ SATINADO | B1041: 01030302 | C1041: =488.35*0.8*0.95 -> 371.146 | D1041: MXP
A1042: ANGULO M-C 90° INOVA,CROMO BRILLANTE | B1042: 01030101 | C1042: =429.67*0.8*0.95 -> 326.5492 | D1042: MXP
A1043: ANGULO M-C 90° INOVA,NIQUEL SATINADO | B1043: 01030102 | C1043: =462.75*0.8*0.95 -> 351.69 | D1043: MXP
...

Sheet Sheet1
B7: CLAVE | C7: CONCEPTO | D7: PRECIO | E7: MONEDA
C8: Silicón Uso General 100% Grado Arq. - Transparente | D8: 76 | F8: Transp.
C9: Silicón Uso General 100% Grado Arq. - Blanco | D9: 76 | F9: Blanco
C10: Silicón Uso General 100% Grado Arq. - Negro | D10: 76 | F10: Negro
C11: Silicón Anti-Hongos - Transparente | D11: 76 | F11: Transparente
C12: Silicón Anti-Hongos - Blanco | D12: 76 | F12: Blanco
C13: Sikasil N-Plus - Transparente | D13: 112 | F13: Transparente
C14: Sikasil N-Plus - Blanco | D14: 112 | F14: Blanco
C15: Sikasil N-Plus - Gris | D15: 112 | F15: Gris
C16: Sikasil N-Plus - Negro | D16: 112 | F16: Negro
C17: Sikasil WS-305 Sellador Estructural - Negro | D17: 168 | F17: Negro
C18: Sikasil WS-305 Sellador Estructural - Blanco | D18: 168 | F18: Blanco
C19: Sikasil WS-305 Sellador Estructural - Gris | D19: 168 | F19: Gris
... C22: U-Seal 907 Poliuretano - Negro | D22: 82 | F22: Gris
C23: U-Seal 907 Poliuretano - Gris | D23: 82
C24: Simp Seal 25 Sellador Hibrido - Blanco | D24: 92 | F24: Blanco, Negro
C25: Simp Seal 25 Sellador Hibrido - Negro | D25: 92 | F25: Gris claro
C26: Simp Seal 25 Sellador Hibrido - Gris Claro | D26: 92
C27: Simp Seal 25 Sellador Hibrido - Gris Europa | D27: 98
C28: Simp Seal 25 Sellador Hibrido - Café Obscuro | D28: 98 | F28: Gris Europa
C29: Simp High Tack Adhesivo Hibrido - Blanco | D29: 126 | F29: Blanco
C30: Acrilastic Sellador Acrílico - Blanco | D30: 46 | F30: Blanco, Negro
C31: Acrilastic Sellador Acrílico - Negro | D31: 46 | F31: Beige, Gris
C32: Acrilastic Sellador Acrílico - Beige | D32: 46
C33: Acrilastic Sellador Acrílico - Gris | D33: 46
C34: Backer Rod Cilíndrico - 1/4" Caja 1,219 ml | D34: 1680 | F34: 1/4" Caja con 1,219 mt.
C35: Backer Rod Cilíndrico - 3/8" Caja con 640 ml | D35: 1215 | F35: 3/8" Caja con 640 mt.
C36: Backer Rod Cilíndrico - 1/2" Caja con 762 ml | D36: 2050 | F36: 1/2" Caja con 762 mt.
C37: Backer Rod Cilíndrico - 3/4" Caja con 335 ml | D37: 1815 | F37: 3/4" Caja con 335 mt
C38: Backer Rod Cilíndrico - 1 " Caja con 182 ml | D38: 1732 | F38: 1 " Caja con 182mt.
C39: Backer Rod Plano Gris - 10 mm X 20 mm | D39: 4.1 | F39: Gris
C40: Cinta Norton Negro - 20 mts Ancho 1/4" X Espesor 1/8" | D40: 83 | E40: Ancho 1/4" X Espesor 1/8" | F40: Negro
C41: Cinta Norton Negro - 20 mts Ancho 3/8" X Espesor 1/8" | D41: 125 | E41: (Rollo c/20 mts.)
C42: Cinta Norton Negro - 20 mts Ancho 1/2" X Espesor 1/8" | D42: 166
C43: Cinta Norton Negro - 20 mts Ancho 3/4" X Espesor 1/8" | D43: 262 | E43: Ancho 3/8" X Espesor 1/8"
C44: Cinta Norton Negro - 15.25 mts Ancho 1/4" X Espesor 1/8" | D44: 102.5 | E44: Ancho 1/4" X Espesor 1/"4 | F44: Negro
C45: Cinta Norton Negro - 15.25 mts Ancho 3/8" X Espesor 1/8" | D45: 154 | E45: (Rollo c/15.25 mts.)
C46: Cinta Norton Negro - 15.25 mts Ancho 1/2" X Espesor 1/8" | D46: 205
C47: Cinta de Polietileno Doble Adhesivo | D47: 220 | E47: Ancho 12 mm X Espesor 1mm | F47: Blanco
C48: Cinta Selladucto | D48: 160 | E48: 48 X 50 mm | F48: Gris
...

Sheet PED-60 CHAVEZ herrajes 00606 EM
A1: PROYECTO | B1: PEDIDO | C1: CLAN | D1: FAMILIA | E1: PROVEEDOR | F1: FECHA DE APROBACION | G1: LUGAR DE ENTREGA | H1: CONCEPTO | I1: SITUACIONES ESPECIALES | J1: IMPORTE
A2: =RESPALDO!F14 -> 00443 JAIME NUNO | B2: =RESPALDO!C13 -> 250 | C2: =RESPALDO!F15 -> MATERIALES | D2: =RESPALDO!C14 -> EM | E2: =RESPALDO!F4 -> JUAN ALEJANDRO CHAVEZ | F2: =RESPALDO!C42 -> 06/11/2025 | G2: =RESPALDO!F16 -> JAIME NUNO | H2: =RESPALDO!C15 -> EMPAQUES | I2: =RESPALDO!L40 -> - | J2: =RESPALDO!I43 -> 4872
